<?xml version="1.0" encoding="utf-8"?>
<robot name="stretch">
	<link name="world">
	</link>
	<link name="link_gripper">
		<inertial>
			<origin rpy="0 0 0" xyz="-0.0170229132730066 0.0131410320934285 -0.0371614759484659"></origin>
			<mass value="0.101902711393094"></mass>
			<inertia ixx="0.001" ixy="0" ixz="0" iyy="0.001" iyz="0" izz="0.001"></inertia>
		</inertial>
		<visual>
			<origin rpy="0 0 0" xyz="0 0 0"></origin>
			<geometry>
				<mesh filename="package://meshes/link_gripper.STL"></mesh>
			</geometry>
			<material name="">
				<color rgba="0.1 0.1 0.1 1"></color>
			</material>
		</visual>
		<collision>
			<origin rpy="0 0 0" xyz="0 0 0"></origin>
			<geometry>
				<mesh filename="package://meshes/link_gripper.STL"></mesh>
			</geometry>
		</collision>
	</link>
	<link name="link_gripper_finger_left">
		<inertial>
			<origin rpy="0 0 0" xyz="0.0945047483510102 0.0124301080924361 -4.44089209850063E-16"></origin>
			<mass value="0.0476207785199474"></mass>
			<inertia ixx="0.001" ixy="0" ixz="0" iyy="0.001" iyz="0" izz="0.001"></inertia>
		</inertial>
		<visual>
			<origin rpy="0 0 0" xyz="0 0 0"></origin>
			<geometry>
				<mesh filename="package://meshes/link_gripper_finger_left.STL" scale="0.9 1.0 1.0"></mesh>
			</geometry>
			<material name="">
				<color rgba="0.5 0.5 0.5 1"></color>
			</material>
		</visual>
		<collision>
			<origin rpy="0 0 0" xyz="0 0 0"></origin>
			<geometry>
				<mesh filename="package://meshes/link_gripper_finger_left.STL" scale="0.9 1.0 1.0"></mesh>
			</geometry>
		</collision>
	</link>
	<link name="link_gripper_fingertip_left">
		<inertial>
			<origin rpy="0 0 0" xyz="-3.16381381648689E-08 -2.91408530639359E-09 0.00812579670381812"></origin>
			<mass value="0.00382159917455729"></mass>
			<inertia ixx="0.001" ixy="0" ixz="0" iyy="0.001" iyz="0" izz="0.001"></inertia>
		</inertial>
		<visual>
			<origin rpy="0 0 0" xyz="0 0 0"></origin>
			<geometry>
				<mesh filename="package://meshes/link_gripper_fingertip_left.STL"></mesh>
			</geometry>
			<material name="">
				<color rgba="0.01 0.01 0.01 1"></color>
			</material>
		</visual>
		<collision>
			<origin rpy="0 0 0" xyz="0 0 0"></origin>
			<geometry>
				<mesh filename="package://meshes/link_gripper_fingertip_left.STL"></mesh>
			</geometry>
		</collision>
	</link>
	<link name="link_gripper_finger_right">
		<inertial>
			<origin rpy="0 0 0" xyz="-0.0945047483510099 -0.0124301080924345 0"></origin>
			<mass value="0.0476207785199481"></mass>
			<inertia ixx="0.001" ixy="0" ixz="0" iyy="0.001" iyz="0" izz="0.001"></inertia>
		</inertial>
		<visual>
			<origin rpy="0 0 0" xyz="0 0 0"></origin>
			<geometry>
				<mesh filename="package://meshes/link_gripper_finger_right.STL" scale="0.9 1.0 1.0"></mesh>
			</geometry>
			<material name="">
				<color rgba="0.5 0.5 0.5 1"></color>
			</material>
		</visual>
		<collision>
			<origin rpy="0 0 0" xyz="0 0 0"></origin>
			<geometry>
				<mesh filename="package://meshes/link_gripper_finger_right.STL" scale="0.9 1.0 1.0"></mesh>
			</geometry>
		</collision>
	</link>
	<link name="link_gripper_fingertip_right">
		<inertial>
			<origin rpy="0 0 0" xyz="2.59386303963494E-08 6.70949018566347E-09 0.00812579516130402"></origin>
			<mass value="0.00382160037319545"></mass>
			<inertia ixx="0.001" ixy="0" ixz="0" iyy="0.001" iyz="0" izz="0.001"></inertia>
		</inertial>
		<visual>
			<origin rpy="0 0 0" xyz="0 0 0"></origin>
			<geometry>
				<mesh filename="package://meshes/link_gripper_fingertip_right.STL"></mesh>
			</geometry>
			<material name="">
				<color rgba="0.01 0.01 0.01 1"></color>
			</material>
		</visual>
		<collision>
			<origin rpy="0 0 0" xyz="0 0 0"></origin>
			<geometry>
				<mesh filename="package://meshes/link_gripper_fingertip_right.STL"></mesh>
			</geometry>
		</collision>
	</link>
	<link name="link_grasp_center"></link>
	<link name="base_link">
		<inertial>
			<origin rpy="0 0 0" xyz="-0.109461304328163 -0.000741018909047708 0.0914915269429946"></origin>
			<mass value="1.0723782659782"></mass>
			<inertia ixx="0.00310580907710135" ixy="1.5182848191076E-06" ixz="0.00041690466732394" iyy="0.00433798719991832" iyz="1.33487716258445E-05" izz="0.0037204727467362"></inertia>
		</inertial>
		<visual>
			<origin rpy="0 0 0" xyz="0 0 0"></origin>
			<geometry>
				<mesh filename="package://meshes/base_link.STL"></mesh>
			</geometry>
			<material name="">
				<color rgba="0.3 0.3 0.35 1"></color>
			</material>
		</visual>
		<collision>
			<origin rpy="0 0 0" xyz="0 0 0"></origin>
			<geometry>
				<mesh filename="package://meshes/base_link.STL"></mesh>
			</geometry>
		</collision>
	</link>
	<link name="link_right_wheel">
		<inertial>
			<origin rpy="0 0 0" xyz="1.25554620866719E-07 3.54748938447003E-07 0.0239581106165018"></origin>
			<mass value="0.01"></mass>
			<inertia ixx="0.001" ixy="0" ixz="0" iyy="0.001" iyz="0" izz="0.001"></inertia>
		</inertial>
		<visual>
			<origin rpy="0 0 0" xyz="0 0 0"></origin>
			<geometry>
				<mesh filename="package://meshes/link_right_wheel.STL"></mesh>
			</geometry>
			<material name="">
				<color rgba="0.1 0.1 0.1 1"></color>
			</material>
		</visual>
		<collision>
			<origin rpy="0 0 0" xyz="0 0 0"></origin>
			<geometry>
				<mesh filename="package://meshes/link_right_wheel.STL"></mesh>
			</geometry>
		</collision>
	</link>
	<link name="link_left_wheel">
		<inertial>
			<origin rpy="0 0 0" xyz="1.2555462092223E-07 -3.54748938502514E-07 -0.0239581106165035"></origin>
			<mass value="0.01"></mass>
			<inertia ixx="0.001" ixy="0" ixz="0" iyy="0.001" iyz="0" izz="0.001"></inertia>
		</inertial>
		<visual>
			<origin rpy="0 0 0" xyz="0 0 0"></origin>
			<geometry>
				<mesh filename="package://meshes/link_left_wheel.STL"></mesh>
			</geometry>
			<material name="">
				<color rgba="0.1 0.1 0.1 1"></color>
			</material>
		</visual>
		<collision>
			<origin rpy="0 0 0" xyz="0 0 0"></origin>
			<geometry>
				<mesh filename="package://meshes/link_left_wheel.STL"></mesh>
			</geometry>
		</collision>
	</link>
	<link name="caster_link">
		<collision>
			<geometry>
				<sphere radius="0.032"></sphere>
			</geometry>
			<origin rpy="0 0 0" xyz="0 0 0"></origin>
			<surface>
				<friction>
					<ode>
						<mu>0</mu>
						<mu2>0</mu2>
						<slip1>1.0</slip1>
						<slip2>1.0</slip2>
					</ode>
				</friction>
			</surface>
		</collision>
		<visual>
			<origin rpy="0 0 0" xyz="0 0 0"></origin>
			<geometry>
				<mesh filename="package://meshes/omni_wheel_m.STL"></mesh>
			</geometry>
			<material name="">
				<color rgba="0.792156862745098 0.819607843137255 0.933333333333333 1"></color>
			</material>
		</visual>
		<inertial>
			<mass value="0.01"></mass>
			<origin xyz="0 0 0"></origin>
			<inertia ixx="0.001" ixy="0" ixz="0" iyy="0.001" iyz="0" izz="0.001"></inertia>
		</inertial>
	</link>
	<link name="link_mast">
		<inertial>
			<origin rpy="0 0 0" xyz="0.00755818572975822 0.773971284176834 0.00647313086620024"></origin>
			<mass value="0.749143203376401"></mass>
			<inertia ixx="0.0709854511954588" ixy="-0.00433428742758457" ixz="-0.000186110788697573" iyy="0.000437922053342648" iyz="-0.00288788257713431" izz="0.071104808501661"></inertia>
		</inertial>
		<visual>
			<origin rpy="0 0 0" xyz="0 0 0"></origin>
			<geometry>
				<mesh filename="package://meshes/link_mast.STL"></mesh>
			</geometry>
			<material name="">
				<color rgba="0.02 0.02 0.02 1"></color>
			</material>
		</visual>
		<collision>
			<origin rpy="0 0 0" xyz="0 0 0"></origin>
			<geometry>
				<mesh filename="package://meshes/link_mast.STL"></mesh>
			</geometry>
		</collision>
	</link>
	<link name="link_lift">
		<inertial>
			<origin rpy="0 0 0" xyz="-0.0547636346252869 0.0380939689802074 0.00933159404448308"></origin>
			<mass value="0.444820831236007"></mass>
			<inertia ixx="0.000567192946271367" ixy="-0.00024607534789508" ixz="-0.000128108442260574" iyy="0.00127108364478659" iyz="7.61916855070339E-06" izz="0.00137296635099006"></inertia>
		</inertial>
		<visual>
			<origin rpy="0 0 0" xyz="0 0 0"></origin>
			<geometry>
				<mesh filename="package://meshes/link_lift.STL"></mesh>
			</geometry>
			<material name="">
				<color rgba="0.02 0.02 0.02 1"></color>
			</material>
		</visual>
		<collision>
			<origin rpy="0 0 0" xyz="0 0 0"></origin>
			<geometry>
				<mesh filename="package://meshes/link_lift.STL"></mesh>
			</geometry>
		</collision>
	</link>
	<link name="link_arm_l4">
		<inertial>
			<origin rpy="0 0 0" xyz="-1.61247276464493E-06 1.54715589201215E-06 -0.0953252706040035"></origin>
			<mass value="0.0676525455789735"></mass>
			<inertia ixx="0.000122002023066796" ixy="7.29593356230121E-13" ixz="9.63170353371061E-09" iyy="0.000122002023127152" iyz="-9.24154949889042E-09" izz="1.46043439809638E-12"></inertia>
		</inertial>
		<visual>
			<origin rpy="0 0 0" xyz="0 0 0"></origin>
			<geometry>
				<mesh filename="package://meshes/link_arm_l4.STL"></mesh>
			</geometry>
			<material name="">
				<color rgba="0.01 0.01 0.01 1"></color>
			</material>
		</visual>
		<collision>
			<origin rpy="0 0 0" xyz="0 0 0"></origin>
			<geometry>
				<mesh filename="package://meshes/link_arm_l4.STL"></mesh>
			</geometry>
		</collision>
	</link>
	<link name="link_arm_l3">
		<inertial>
			<origin rpy="0 0 0" xyz="-3.34873468621488E-07 4.7411336306924E-07 -0.0974069598289041"></origin>
			<mass value="0.0626921047058405"></mass>
			<inertia ixx="0.001" ixy="0" ixz="0" iyy="0.001" iyz="0" izz="0.001"></inertia>
		</inertial>
		<visual>
			<origin rpy="0 0 0" xyz="0 0 0"></origin>
			<geometry>
				<mesh filename="package://meshes/link_arm_l3.STL"></mesh>
			</geometry>
			<material name="">
				<color rgba="0.01 0.01 0.01 1"></color>
			</material>
		</visual>
		<collision>
			<origin rpy="0 0 0" xyz="0 0 0"></origin>
			<geometry>
				<mesh filename="package://meshes/link_arm_l3.STL"></mesh>
			</geometry>
		</collision>
	</link>
	<link name="link_arm_l2">
		<inertial>
			<origin rpy="0 0 0" xyz="-3.31043560508615E-07 3.13422303999111E-07 -0.097255883541891"></origin>
			<mass value="0.0569074368576238"></mass>
			<inertia ixx="0.001" ixy="0" ixz="0" iyy="0.001" iyz="0" izz="0.001"></inertia>
		</inertial>
		<visual>
			<origin rpy="0 0 0" xyz="0 0 0"></origin>
			<geometry>
				<mesh filename="package://meshes/link_arm_l2.STL"></mesh>
			</geometry>
			<material name="">
				<color rgba="0.01 0.01 0.01 1"></color>
			</material>
		</visual>
		<collision>
			<origin rpy="0 0 0" xyz="0 0 0"></origin>
			<geometry>
				<mesh filename="package://meshes/link_arm_l2.STL"></mesh>
			</geometry>
		</collision>
	</link>
	<link name="link_arm_l1">
		<inertial>
			<origin rpy="0 0 0" xyz="-3.36876635420591E-07 3.05876091066803E-07 -0.0969117032232756"></origin>
			<mass value="0.0511763619538321"></mass>
			<inertia ixx="0.001" ixy="0" ixz="0" iyy="0.001" iyz="0" izz="0.001"></inertia>
		</inertial>
		<visual>
			<origin rpy="0 0 0" xyz="0 0 0"></origin>
			<geometry>
				<mesh filename="package://meshes/link_arm_l1.STL"></mesh>
			</geometry>
			<material name="">
				<color rgba="0.01 0.01 0.01 1"></color>
			</material>
		</visual>
		<collision>
			<origin rpy="0 0 0" xyz="0 0 0"></origin>
			<geometry>
				<mesh filename="package://meshes/link_arm_l1.STL"></mesh>
			</geometry>
		</collision>
	</link>
	<link name="link_arm_l0">
		<inertial>
			<origin rpy="0 0 0" xyz="0.0230715049668191 -0.00195115833662818 -0.0360646347160285"></origin>
			<mass value="0.101241250325294"></mass>
			<inertia ixx="0.001" ixy="0" ixz="0" iyy="0.001" iyz="0" izz="0.001"></inertia>
		</inertial>
		<visual>
			<origin rpy="0 0 0" xyz="0 0 0"></origin>
			<geometry>
				<mesh filename="package://meshes/link_arm_l0.STL"></mesh>
			</geometry>
			<material name="">
				<color rgba="0.01 0.01 0.01 1"></color>
			</material>
		</visual>
		<collision>
			<origin rpy="0 0 0" xyz="0 0 0"></origin>
			<geometry>
				<mesh filename="package://meshes/link_arm_l0.STL"></mesh>
			</geometry>
		</collision>
	</link>
	<link name="link_wrist_yaw">
		<inertial>
			<origin rpy="0 0 0" xyz="-8.02795716750571E-06 1.93811447768422E-05 0.018946700595851"></origin>
			<mass value="0.0405398981326229"></mass>
			<inertia ixx="0.001" ixy="0" ixz="0" iyy="0.001" iyz="0" izz="0.001"></inertia>
		</inertial>
		<visual>
			<origin rpy="0 0 0" xyz="0 0 0"></origin>
			<geometry>
				<mesh filename="package://meshes/link_wrist_yaw.STL"></mesh>
			</geometry>
			<material name="">
				<color rgba="0.01 0.01 0.01 1"></color>
			</material>
		</visual>
		<collision>
			<origin rpy="0 0 0" xyz="0 0 0"></origin>
			<geometry>
				<mesh filename="package://meshes/link_wrist_yaw.STL"></mesh>
			</geometry>
		</collision>
	</link>
	<link name="link_head">
		<inertial>
			<origin rpy="0 0 0" xyz="0.0372933550588956 0.045509432985552 0.0281136801213409"></origin>
			<mass value="0.129454717596498"></mass>
			<inertia ixx="0.001" ixy="0" ixz="0" iyy="0.001" iyz="0" izz="0.001"></inertia>
		</inertial>
		<visual>
			<origin rpy="0 0 0" xyz="0 0 0"></origin>
			<geometry>
				<mesh filename="package://meshes/link_head.STL"></mesh>
			</geometry>
			<material name="">
				<color rgba="0.02 0.02 0.02 1"></color>
			</material>
		</visual>
		<collision>
			<origin rpy="0 0 0" xyz="0 0 0"></origin>
			<geometry>
				<mesh filename="package://meshes/link_head.STL"></mesh>
			</geometry>
		</collision>
	</link>
	<link name="link_head_pan">
		<inertial>
			<origin rpy="0 0 0" xyz="-0.00116200255310878 0.0130365621706306 0.00137629842298681"></origin>
			<mass value="0.035858341182617"></mass>
			<inertia ixx="0.001" ixy="0" ixz="0" iyy="0.001" iyz="0" izz="0.001"></inertia>
		</inertial>
		<visual>
			<origin rpy="0 0 0" xyz="0 0 0"></origin>
			<geometry>
				<mesh filename="package://meshes/link_head_pan.STL"></mesh>
			</geometry>
			<material name="">
				<color rgba="0.01 0.01 0.01 1"></color>
			</material>
		</visual>
		<collision>
			<origin rpy="0 0 0" xyz="0 0 0"></origin>
			<geometry>
				<mesh filename="package://meshes/link_head_pan.STL"></mesh>
			</geometry>
		</collision>
	</link>
	<link name="link_head_tilt">
		<inertial>
			<origin rpy="0 0 0" xyz="0.00920211049011871 -0.0279724762416447 0.0306580436227023"></origin>
			<mass value="0.0701242408063442"></mass>
			<inertia ixx="0.001" ixy="0" ixz="0" iyy="0.001" iyz="0" izz="0.001"></inertia>
		</inertial>
		<visual>
			<origin rpy="0 0 0" xyz="0 0 0"></origin>
			<geometry>
				<mesh filename="package://meshes/link_head_tilt.STL"></mesh>
			</geometry>
			<material name="">
				<color rgba="0.1 0.1 0.1 1"></color>
			</material>
		</visual>
		<collision>
			<origin rpy="0 0 0" xyz="0 0 0"></origin>
			<geometry>
				<mesh filename="package://meshes/link_head_tilt.STL"></mesh>
			</geometry>
		</collision>
	</link>
	<link name="link_aruco_right_base">
		<inertial>
			<origin rpy="0 0 0" xyz="0 0 -5.00000000014378E-07"></origin>
			<mass value="3.59999999990368E-06"></mass>
			<inertia ixx="0" ixy="0" ixz="0" iyy="0" iyz="0" izz="0"></inertia>
		</inertial>
		<visual>
			<origin rpy="0 0 0" xyz="0 0 0"></origin>
			<geometry>
				<mesh filename="package://meshes/link_aruco_right_base.STL"></mesh>
			</geometry>
			<material name="">
				<color rgba="0.01 0.01 0.01 1"></color>
			</material>
		</visual>
		<collision>
			<origin rpy="0 0 0" xyz="0 0 0"></origin>
			<geometry>
				<mesh filename="package://meshes/link_aruco_right_base.STL"></mesh>
			</geometry>
		</collision>
	</link>
	<link name="link_aruco_left_base">
		<inertial>
			<origin rpy="0 0 0" xyz="0 0 -5.00000000014378E-07"></origin>
			<mass value="3.59999999990368E-06"></mass>
			<inertia ixx="0" ixy="0" ixz="0" iyy="0" iyz="0" izz="0"></inertia>
		</inertial>
		<visual>
			<origin rpy="0 0 0" xyz="0 0 0"></origin>
			<geometry>
				<mesh filename="package://meshes/link_aruco_left_base.STL"></mesh>
			</geometry>
			<material name="">
				<color rgba="0.792156862745098 0.819607843137255 0.933333333333333 1"></color>
			</material>
		</visual>
		<collision>
			<origin rpy="0 0 0" xyz="0 0 0"></origin>
			<geometry>
				<mesh filename="package://meshes/link_aruco_left_base.STL"></mesh>
			</geometry>
		</collision>
	</link>
	<link name="link_aruco_shoulder">
		<inertial>
			<origin rpy="0 0 0" xyz="-2.77555756156289E-17 2.56739074444567E-16 -0.000125000000000042"></origin>
			<mass value="0"></mass>
			<inertia ixx="0" ixy="0" ixz="0" iyy="0" iyz="0" izz="0"></inertia>
		</inertial>
		<visual>
			<origin rpy="0 0 0" xyz="0 0 0"></origin>
			<geometry>
				<mesh filename="package://meshes/link_aruco_shoulder.STL"></mesh>
			</geometry>
			<material name="">
				<color rgba="0.792156862745098 0.819607843137255 0.933333333333333 1"></color>
			</material>
		</visual>
		<collision>
			<origin rpy="0 0 0" xyz="0 0 0"></origin>
			<geometry>
				<mesh filename="package://meshes/link_aruco_shoulder.STL"></mesh>
			</geometry>
		</collision>
	</link>
	<link name="link_aruco_top_wrist">
		<inertial>
			<origin rpy="0 0 0" xyz="1.11022302462516E-16 3.05311331771918E-16 -0.00012499999999821"></origin>
			<mass value="0"></mass>
			<inertia ixx="0" ixy="0" ixz="0" iyy="0" iyz="0" izz="0"></inertia>
		</inertial>
		<visual>
			<origin rpy="0 0 0" xyz="0 0 0"></origin>
			<geometry>
				<mesh filename="package://meshes/link_aruco_top_wrist.STL"></mesh>
			</geometry>
			<material name="">
				<color rgba="0.792156862745098 0.819607843137255 0.933333333333333 1"></color>
			</material>
		</visual>
		<collision>
			<origin rpy="0 0 0" xyz="0 0 0"></origin>
			<geometry>
				<mesh filename="package://meshes/link_aruco_top_wrist.STL"></mesh>
			</geometry>
		</collision>
	</link>
	<link name="link_aruco_inner_wrist">
		<inertial>
			<origin rpy="0 0 0" xyz="8.32667268468867E-17 1.77635683940025E-15 -0.000125000000000264"></origin>
			<mass value="0"></mass>
			<inertia ixx="0" ixy="0" ixz="0" iyy="0" iyz="0" izz="0"></inertia>
		</inertial>
		<visual>
			<origin rpy="0 0 0" xyz="0 0 0"></origin>
			<geometry>
				<mesh filename="package://meshes/link_aruco_inner_wrist.STL"></mesh>
			</geometry>
			<material name="">
				<color rgba="0.792156862745098 0.819607843137255 0.933333333333333 1"></color>
			</material>
		</visual>
		<collision>
			<origin rpy="0 0 0" xyz="0 0 0"></origin>
			<geometry>
				<mesh filename="package://meshes/link_aruco_inner_wrist.STL"></mesh>
			</geometry>
		</collision>
	</link>
	<link name="camera_bottom_screw_frame"></link>
	<link name="camera_link">
		<visual>
			<origin rpy="1.5707963267948966 0 1.5707963267948966" xyz="0.0043 -0.0175 0"></origin>
			<geometry>
				<mesh filename="package://meshes/d435.dae"></mesh>
			</geometry>
			<material name="">
				<color rgba="0.01 0.01 0.01 1"></color>
			</material>
		</visual>
		<collision>
			<origin rpy="0 0 0" xyz="0 -0.0175 0"></origin>
			<geometry>
				<box size="0.02505 0.09 0.025"></box>
			</geometry>
		</collision>
		<inertial>
			<mass value="0.072"></mass>
			<origin xyz="0 0 0"></origin>
			<inertia ixx="0.003881243" ixy="0.0" ixz="0.0" iyy="0.000498940" iyz="0.0" izz="0.003879257"></inertia>
		</inertial>
	</link>
	<link name="camera_depth_frame"></link>
	<link name="camera_depth_optical_frame"></link>
	<link name="camera_infra1_frame"></link>
	<link name="camera_infra1_optical_frame"></link>
	<link name="camera_infra2_frame"></link>
	<link name="camera_infra2_optical_frame"></link>
	<link name="camera_color_frame"></link>
	<link name="camera_color_optical_frame"></link>
	<link name="camera_color_optical_frame_rotated"></link>
	<link name="camera_accel_frame"></link>
	<link name="camera_accel_optical_frame"></link>
	<link name="camera_gyro_frame"></link>
	<link name="camera_gyro_optical_frame"></link>
	<link name="laser">
		<inertial>
			<origin rpy="0 0 0" xyz="0 0 -0.000755956127492408"></origin>
			<mass value="0.0749979022894495"></mass>
			<inertia ixx="0" ixy="0" ixz="0" iyy="0" iyz="0" izz="0"></inertia>
		</inertial>
		<visual>
			<origin rpy="0 0 0" xyz="0 0 0"></origin>
			<geometry>
				<mesh filename="package://meshes/laser.STL"></mesh>
			</geometry>
			<material name="">
				<color rgba="0.02 0.02 0.02 1"></color>
			</material>
		</visual>
		<collision>
			<origin rpy="0 0 0" xyz="0 0 0"></origin>
			<geometry>
				<mesh filename="package://meshes/laser.STL"></mesh>
			</geometry>
		</collision>
	</link>
	<link name="base_imu">
		<inertial>
			<origin rpy="0 0 0" xyz="0.00300349280517617 0.00149777182047641 -0.00193103885249443"></origin>
			<mass value="0.000901473198307758"></mass>
			<inertia ixx="2.83324000746358E-08" ixy="-2.10106175504755E-10" ixz="1.86717014516205E-10" iyy="5.35315990744214E-08" iyz="9.31114208976591E-11" izz="8.13221670783358E-08"></inertia>
		</inertial>
		<visual>
			<origin rpy="0 0 0" xyz="0 0 0"></origin>
			<geometry>
				<mesh filename="package://meshes/base_imu.STL"></mesh>
			</geometry>
			<material name="">
				<color rgba="0 0.772549019607843 0.207843137254902 1"></color>
			</material>
		</visual>
		<collision>
			<origin rpy="0 0 0" xyz="0 0 0"></origin>
			<geometry>
				<mesh filename="package://meshes/base_imu.STL"></mesh>
			</geometry>
		</collision>
	</link>
	<link name="respeaker_base">
		<inertial>
			<origin rpy="0 0 0" xyz="-0.00078082896792734 0.00765742173486017 -0.0042488298301937"></origin>
			<mass value="0.00969129410417277"></mass>
			<inertia ixx="8.95656300428405E-07" ixy="2.67330745809535E-08" ixz="-3.84519793580934E-08" iyy="4.0421099617056E-07" iyz="3.15533542838673E-07" izz="7.08282597118018E-07"></inertia>
		</inertial>
		<visual>
			<origin rpy="0 0 0" xyz="0 0 0"></origin>
			<geometry>
				<mesh filename="package://meshes/link_respeaker.STL"></mesh>
			</geometry>
			<material name="">
				<color rgba="0 0 0 1"></color>
			</material>
		</visual>
		<collision>
			<origin rpy="0 0 0" xyz="0 0 0"></origin>
			<geometry>
				<mesh filename="package://meshes/link_respeaker.STL"></mesh>
			</geometry>
		</collision>
	</link>
	<link name="base_link_x"></link>
	<link name="base_link_y"></link>
	<link name="base_link_yaw"></link>
	<joint name="joint_gripper" type="fixed">
		<origin rpy="3.14159 0 -1.5708" xyz="0 0 0"></origin>
		<parent link="link_wrist_yaw"></parent>
		<child link="link_gripper"></child>
		<axis xyz="0 0 0"></axis>
	</joint>
	<joint name="joint_gripper_finger_left" type="revolute">
		<origin rpy="2.1762E-15 0.5236 3.1416" xyz="-0.047231 -0.010151 -0.04679"></origin>
		<parent link="link_gripper"></parent>
		<child link="link_gripper_finger_left"></child>
		<axis xyz="0 0 1"></axis>
		<limit effort="100" lower="-0.6" upper="0.6" velocity="1.0"></limit>
	</joint>
	<joint name="joint_gripper_fingertip_left" type="fixed">
		<origin rpy="-1.5708 -4.774E-15 -2.5545" xyz="0.171099 0.014912 0"></origin>
		<parent link="link_gripper_finger_left"></parent>
		<child link="link_gripper_fingertip_left"></child>
		<axis xyz="0 0 0"></axis>
	</joint>
	<joint name="joint_gripper_finger_right" type="revolute">
		<origin rpy="3.1416 -0.5236 1.2943E-15" xyz="-0.047231 0.010049 -0.04679"></origin>
		<parent link="link_gripper"></parent>
		<child link="link_gripper_finger_right"></child>
		<axis xyz="0 0 1"></axis>
		<limit effort="100" lower="-0.6" upper="0.6" velocity="1.0"></limit>
	</joint>
	<joint name="joint_gripper_fingertip_right" type="fixed">
		<origin rpy="-1.5708 -2.0539E-15 0.58705" xyz="-0.171099 -0.014912 0"></origin>
		<parent link="link_gripper_finger_right"></parent>
		<child link="link_gripper_fingertip_right"></child>
		<axis xyz="0 0 0"></axis>
	</joint>
	<joint name="joint_grasp_center" type="fixed">
		<origin rpy="0 0 3.141579" xyz="-0.205478 0 -0.138154"></origin>
		<parent link="link_gripper"></parent>
		<child link="link_grasp_center"></child>
	</joint>
	<joint name="joint_right_wheel" type="continuous">
		<origin rpy="-1.57079632679489 -1.11022302462516E-16 7.28583859910277E-17" xyz="-0.00300000000000034 -0.15765 0.0508000000000004"></origin>
		<parent link="base_link"></parent>
		<child link="link_right_wheel"></child>
		<axis xyz="0 0 1"></axis>
		<dynamics damping="21.75" friction="10.48" spring_reference="0" spring_stiffness="{joint_spring_stiffness}"></dynamics>
	</joint>
	<joint name="joint_left_wheel" type="continuous">
		<origin rpy="-1.5707963267949 3.16227047920818E-31 7.88745438253713E-16" xyz="-0.00300000000001899 0.15765 0.0507999999999994"></origin>
		<parent link="base_link"></parent>
		<child link="link_left_wheel"></child>
		<axis xyz="0 0 1"></axis>
		<dynamics damping="21.75" friction="10.48" spring_reference="0" spring_stiffness="{joint_spring_stiffness}"></dynamics>
	</joint>
	<joint name="caster_joint" type="fixed">
		<parent link="base_link"></parent>
		<child link="caster_link"></child>
		<origin rpy="-1.5707963267948966 0 0" xyz="-0.245 0.0 0.032"></origin>
		<axis xyz="0 0 1"></axis>
	</joint>
	<joint name="joint_mast" type="fixed">
		<origin rpy="1.5707963267949 0 0.00925318926571245" xyz="-0.07 0.134999999999998 0.0284000000000001"></origin>
		<parent link="base_link"></parent>
		<child link="link_mast"></child>
		<axis xyz="0 0 0"></axis>
	</joint>
	<joint name="joint_lift" type="prismatic">
		<origin rpy="-1.57079632679552 1.5615431375292 -6.2942004366467E-13" xyz="-0.0369217062323472 0.165471199999996 -0.000341653286793524"></origin>
		<parent link="link_mast"></parent>
		<child link="link_lift"></child>
		<axis xyz="0 0 1"></axis>
		<limit effort="100" lower="0.0" upper="1.1" velocity="1.0"></limit>
	</joint>
	<joint name="joint_arm_l4" type="fixed">
		<origin rpy="1.5708 -3.1019E-16 -1.5708" xyz="-0.25471 0 0"></origin>
		<parent link="link_lift"></parent>
		<child link="link_arm_l4"></child>
		<axis xyz="0 0 0"></axis>
	</joint>
	<joint name="joint_arm_l3" type="prismatic">
		<origin rpy="3.5742E-16 3.2123E-16 -2.4565E-16" xyz="0 0 0.013"></origin>
		<parent link="link_arm_l4"></parent>
		<child link="link_arm_l3"></child>
		<axis xyz="0 0 1"></axis>
		<limit effort="100" lower="0.0" upper="0.13" velocity="1.0"></limit>
	</joint>
	<joint name="joint_arm_l2" type="prismatic">
		<origin rpy="2.91385731014123E-16 4.44300759504684E-17 3.25691080516352E-16" xyz="0 0 0.013"></origin>
		<parent link="link_arm_l3"></parent>
		<child link="link_arm_l2"></child>
		<axis xyz="0 0 1"></axis>
		<limit effort="100" lower="0.0" upper="0.13" velocity="1.0"></limit>
	</joint>
	<joint name="joint_arm_l1" type="prismatic">
		<origin rpy="7.41596560408007E-17 1.33876788296791E-16 -2.44545873596083E-16" xyz="0 0 0.013"></origin>
		<parent link="link_arm_l2"></parent>
		<child link="link_arm_l1"></child>
		<axis xyz="0 0 1"></axis>
		<limit effort="100" lower="0.0" upper="0.13" velocity="1.0"></limit>
	</joint>
	<joint name="joint_arm_l0" type="prismatic">
		<origin rpy="-3.05317390622457E-16 -4.23236224076729E-16 -2.68425135229209E-17" xyz="0 0 -0.0137499999999938"></origin>
		<parent link="link_arm_l1"></parent>
		<child link="link_arm_l0"></child>
		<axis xyz="0 0 1"></axis>
		<limit effort="100" lower="0.0" upper="0.13" velocity="1.0"></limit>
	</joint>
	<joint name="joint_wrist_yaw" type="revolute">
		<origin rpy="1.5708 4.2595E-14 2.6415E-15" xyz="0.083 -0.03075 0"></origin>
		<parent link="link_arm_l0"></parent>
		<child link="link_wrist_yaw"></child>
		<axis xyz="0 0 -1"></axis>
		<limit effort="100" lower="-1.75" upper="4.0" velocity="1.0"></limit>
	</joint>
	<joint name="joint_head" type="fixed">
		<origin rpy="1.5708 -1.5615 3.1416" xyz="0 1.33 0"></origin>
		<parent link="link_mast"></parent>
		<child link="link_head"></child>
		<axis xyz="0 0 0"></axis>
	</joint>
	<joint name="joint_head_pan" type="revolute">
		<origin rpy="-6.4986E-15 -6.068E-24 1.5708" xyz="0.135 0.0731 -0.003"></origin>
		<parent link="link_head"></parent>
		<child link="link_head_pan"></child>
		<axis xyz="0 0 1"></axis>
		<limit effort="100" lower="-3.9" upper="1.5" velocity="1.0"></limit>
	</joint>
	<joint name="joint_head_tilt" type="revolute">
		<origin rpy="1.5708 6.068E-24 -2.5165E-15" xyz="-0.0013 0.027507 -0.053311"></origin>
		<parent link="link_head_pan"></parent>
		<child link="link_head_tilt"></child>
		<axis xyz="0 0 1"></axis>
		<limit effort="100" lower="-1.53" upper="0.79" velocity="1.0"></limit>
	</joint>
	<joint name="joint_aruco_right_base" type="fixed">
		<origin rpy="0 0 -1.5707963267949" xyz="-0.00500000000000014 -0.1304972 0.1597482"></origin>
		<parent link="base_link"></parent>
		<child link="link_aruco_right_base"></child>
		<axis xyz="0 0 0"></axis>
	</joint>
	<joint name="joint_aruco_left_base" type="fixed">
		<origin rpy="0 0 -1.5707963267949" xyz="-0.00500000000000014 0.1304972 0.1597482"></origin>
		<parent link="base_link"></parent>
		<child link="link_aruco_left_base"></child>
		<axis xyz="0 0 0"></axis>
	</joint>
	<joint name="joint_aruco_shoulder" type="fixed">
		<origin rpy="-1.53998860117704E-29 3.55962409571165E-15 0.0" xyz="-0.0133768876375287 0.0558540528812078 0.0861368272417975"></origin>
		<parent link="link_lift"></parent>
		<child link="link_aruco_shoulder"></child>
		<axis xyz="0 0 0"></axis>
	</joint>
	<joint name="joint_aruco_top_wrist" type="fixed">
		<origin rpy="1.5707963267949 -8.03728587323464E-15 3.14159265358979" xyz="0.0472500000000019 0.0292850000000015 0"></origin>
		<parent link="link_arm_l0"></parent>
		<child link="link_aruco_top_wrist"></child>
		<axis xyz="0 0 0"></axis>
	</joint>
	<joint name="joint_aruco_inner_wrist" type="fixed">
		<origin rpy="3.14159265358979 4.23377442363088E-14 3.14159265358979" xyz="0.0472499999999947 -0.0119000000000034 -0.0272499999991938"></origin>
		<parent link="link_arm_l0"></parent>
		<child link="link_aruco_inner_wrist"></child>
		<axis xyz="0 0 0"></axis>
	</joint>
	<joint name="camera_joint" type="fixed">
		<origin rpy="0.0 0.0 0.0" xyz="0.03 -0.0122 0.0182"></origin>
		<parent link="link_head_tilt"></parent>
		<child link="camera_bottom_screw_frame"></child>
	</joint>
	<joint name="camera_link_joint" type="fixed">
		<origin rpy="0 0 0" xyz="0.010600000000000002 0.0175 0.0125"></origin>
		<parent link="camera_bottom_screw_frame"></parent>
		<child link="camera_link"></child>
	</joint>
	<joint name="camera_depth_joint" type="fixed">
		<origin rpy="0 0 0" xyz="0 0 0"></origin>
		<parent link="camera_link"></parent>
		<child link="camera_depth_frame"></child>
	</joint>
	<joint name="camera_depth_optical_joint" type="fixed">
		<origin rpy="-1.5707963267948966 0 -1.5707963267948966" xyz="0 0 0"></origin>
		<parent link="camera_depth_frame"></parent>
		<child link="camera_depth_optical_frame"></child>
	</joint>
	<joint name="camera_infra1_joint" type="fixed">
		<origin rpy="0 0 0" xyz="0 0.0 0"></origin>
		<parent link="camera_link"></parent>
		<child link="camera_infra1_frame"></child>
	</joint>
	<joint name="camera_infra1_optical_joint" type="fixed">
		<origin rpy="-1.5707963267948966 0 -1.5707963267948966" xyz="0 0 0"></origin>
		<parent link="camera_infra1_frame"></parent>
		<child link="camera_infra1_optical_frame"></child>
	</joint>
	<joint name="camera_infra2_joint" type="fixed">
		<origin rpy="0 0 0" xyz="0 -0.05 0"></origin>
		<parent link="camera_link"></parent>
		<child link="camera_infra2_frame"></child>
	</joint>
	<joint name="camera_infra2_optical_joint" type="fixed">
		<origin rpy="-1.5707963267948966 0 -1.5707963267948966" xyz="0 0 0"></origin>
		<parent link="camera_infra2_frame"></parent>
		<child link="camera_infra2_optical_frame"></child>
	</joint>
	<joint name="camera_color_joint" type="fixed">
		<origin rpy="0 0 0" xyz="0 0.015 0"></origin>
		<parent link="camera_link"></parent>
		<child link="camera_color_frame"></child>
	</joint>
	<joint name="camera_color_optical_joint" type="fixed">
		<origin rpy="-1.5707963267948966 0 -1.5707963267948966" xyz="0 0 0"></origin>
		<parent link="camera_color_frame"></parent>
		<child link="camera_color_optical_frame"></child>
	</joint>
	<joint name="camera_color_optical_rotated_joint" type="fixed">
		<origin rpy="0 0 -1.5707963267948966" xyz="0 0 0"></origin>
		<parent link="camera_color_optical_frame"></parent>
		<child link="camera_color_optical_frame_rotated"></child>
	</joint>
	<joint name="camera_accel_joint" type="fixed">
		<origin rpy="0 0 0" xyz="-0.01174 -0.00552 0.0051"></origin>
		<parent link="camera_link"></parent>
		<child link="camera_accel_frame"></child>
	</joint>
	<joint name="camera_accel_optical_joint" type="fixed">
		<origin rpy="-1.5707963267948966 0 -1.5707963267948966" xyz="0 0 0"></origin>
		<parent link="camera_accel_frame"></parent>
		<child link="camera_accel_optical_frame"></child>
	</joint>
	<joint name="camera_gyro_joint" type="fixed">
		<origin rpy="0 0 0" xyz="-0.01174 -0.00552 0.0051"></origin>
		<parent link="camera_link"></parent>
		<child link="camera_gyro_frame"></child>
	</joint>
	<joint name="camera_gyro_optical_joint" type="fixed">
		<origin rpy="-1.5707963267948966 0 -1.5707963267948966" xyz="0 0 0"></origin>
		<parent link="camera_gyro_frame"></parent>
		<child link="camera_gyro_optical_frame"></child>
	</joint>
	<joint name="joint_laser" type="fixed">
		<origin rpy="0 0 -3.14159265358979" xyz="0.000502800000000914 0 0.1664"></origin>
		<parent link="base_link"></parent>
		<child link="laser"></child>
		<axis xyz="0 0 0"></axis>
	</joint>
	<joint name="joint_base_imu" type="fixed">
		<origin rpy="-3.1416 0 -1.5708" xyz="-0.12838 0.0031592 0.1474"></origin>
		<parent link="base_link"></parent>
		<child link="base_imu"></child>
		<axis xyz="0 0 0"></axis>
	</joint>
	<joint name="joint_respeaker" type="fixed">
		<origin rpy="1.57079632679553 0.0 3.14159265358916" xyz="1.09074743137871E-05 1.36992 0.00303572796911382"></origin>
		<parent link="link_mast"></parent>
		<child link="respeaker_base"></child>
		<axis xyz="0 0 0"></axis>
	</joint>
	<joint name="joint_base_link_x" type="prismatic">
		<origin rpy="0 0 0" xyz="0 0 0"></origin>
		<parent link="world"></parent>
		<child link="base_link_x"></child>
		<axis xyz="1 0 0"></axis>
		<limit effort="100" lower="-10" upper="10" velocity="1.0"></limit>
	</joint>
	<joint name="joint_base_link_y" type="prismatic">
		<origin rpy="0 0 0" xyz="0 0 0"></origin>
		<parent link="base_link_x"></parent>
		<child link="base_link_y"></child>
		<axis xyz="0 1 0"></axis>
		<limit effort="100" lower="-10" upper="10" velocity="1.0"></limit>
	</joint>
	<joint name="joint_base_link_yaw" type="revolute">
		<origin rpy="0 0 0" xyz="0 0 0"></origin>
		<parent link="base_link_y"></parent>
		<child link="base_link_yaw"></child>
		<axis xyz="0 0 1"></axis>
		<limit effort="100" lower="-3.14159" upper="3.14159" velocity="1.0"></limit>
	</joint>
	<joint name="joint_base_link" type="fixed">
		<origin rpy="0 0 0" xyz="0 0 0"></origin>
		<parent link="base_link_yaw"></parent>
		<child link="base_link"></child>
	</joint>
	<material name="aluminum">
		<color rgba="0.5 0.5 0.5 1"></color>
	</material>
	<material name="plastic">
		<color rgba="0.1 0.1 0.1 1"></color>
	</material>
</robot>