<?xml version="1.0" ?>
<!-- =================================================================================== -->
<!-- |    This document was autogenerated by xacro from ur5_robotiq_robot_limited.urdf.xacro | -->
<!-- |    EDITING THIS FILE BY HAND IS NOT RECOMMENDED                                 | -->
<!-- =================================================================================== -->
<robot name="ur5_robotiq85">
  <gazebo>
    <plugin filename="libgazebo_ros_control.so" name="ros_control">
      <!--robotNamespace>/</robotNamespace-->
      <!--robotSimType>gazebo_ros_control/DefaultRobotHWSim</robotSimType-->
    </plugin>
    <!--
    <plugin name="gazebo_ros_power_monitor_controller" filename="libgazebo_ros_power_monitor.so">
      <alwaysOn>true</alwaysOn>
      <updateRate>1.0</updateRate>
      <timeout>5</timeout>
      <powerStateTopic>power_state</powerStateTopic>
      <powerStateRate>10.0</powerStateRate>
      <fullChargeCapacity>87.78</fullChargeCapacity>     
      <dischargeRate>-474</dischargeRate>
      <chargeRate>525</chargeRate>
      <dischargeVoltage>15.52</dischargeVoltage>
      <chargeVoltage>16.41</chargeVoltage>
    </plugin>
-->
  </gazebo>
  <!-- measured from model -->
  <!-- measured from model -->
  <!--property name="shoulder_height" value="0.089159" /-->
  <!--property name="shoulder_offset" value="0.13585" /-->
  <!-- shoulder_offset - elbow_offset + wrist_1_length = 0.10915 -->
  <!--property name="upper_arm_length" value="0.42500" /-->
  <!--property name="elbow_offset" value="0.1197" /-->
  <!-- CAD measured -->
  <!--property name="forearm_length" value="0.39225" /-->
  <!--property name="wrist_1_length" value="0.093" /-->
  <!-- CAD measured -->
  <!--property name="wrist_2_length" value="0.09465" /-->
  <!-- In CAD this distance is 0.930, but in the spec it is 0.09465 -->
  <!--property name="wrist_3_length" value="0.0823" /-->
  <!-- manually measured -->
  <link name="base_link">
    <visual>
      <geometry>
        <mesh filename="package://meshes/ur5/visual/base.dae"/>
      </geometry>
      <material name="LightGrey">
        <color rgba="0.7 0.7 0.7 1.0"/>
      </material>
    </visual>
    <collision>
      <geometry>
        <mesh filename="package://meshes/ur5/collision/base.stl"/>
      </geometry>
    </collision>
    <inertial>
      <mass value="4.0"/>
      <origin rpy="0 0 0" xyz="0.0 0.0 0.0"/>
      <inertia ixx="0.00443333156" ixy="0.0" ixz="0.0" iyy="0.00443333156" iyz="0.0" izz="0.0072"/>
    </inertial>
  </link>
  <joint name="shoulder_pan_joint" type="revolute">
    <parent link="base_link"/>
    <child link="shoulder_link"/>
    <origin rpy="0 0.0 0" xyz="0.0 0.0 0.089159"/>
    <axis xyz="0 0 1"/>
    <!-- <limit effort="150.0" lower="-3.14159265" upper="3.14159265" velocity="3.15"/> -->
    <limit effort="150.0" lower="-3.14159265" upper="3.14159265" velocity="0.5"/>
    <dynamics damping="0.0" friction="0.0"/>
  </joint>
  <link name="shoulder_link">
    <visual>
      <geometry>
        <mesh filename="package://meshes/ur5/visual/shoulder.dae"/>
      </geometry>
      <material name="LightGrey">
        <color rgba="0.7 0.7 0.7 1.0"/>
      </material>
    </visual>
    <collision>
      <geometry>
        <mesh filename="package://meshes/ur5/collision/shoulder.stl"/>
      </geometry>
    </collision>
    <inertial>
      <mass value="3.7"/>
      <origin rpy="0 0 0" xyz="0.0 0.0 0.0"/>
      <inertia ixx="0.010267495893" ixy="0.0" ixz="0.0" iyy="0.010267495893" iyz="0.0" izz="0.00666"/>
    </inertial>
  </link>
  <joint name="shoulder_lift_joint" type="revolute">
    <parent link="shoulder_link"/>
    <child link="upper_arm_link"/>
    <origin rpy="0.0 1.570796325 0.0" xyz="0.0 0.13585 0.0"/>
    <!--      <origin xyz="0.0 ${shoulder_offset} 0.0" rpy="0.0 ${angle_offset} 0.0" /> -->
    <axis xyz="0 1 0"/>
    <!-- <limit effort="150.0" lower="-3.14159265" upper="3.14159265" velocity="3.15"/> -->
    <limit effort="150.0" lower="-3.14159265" upper="3.14159265" velocity="0.5"/>
    <dynamics damping="0.0" friction="0.0"/>
  </joint>
  <link name="upper_arm_link">
    <visual>
      <geometry>
        <mesh filename="package://meshes/ur5/visual/upperarm.dae"/>
      </geometry>
      <material name="LightGrey">
        <color rgba="0.7 0.7 0.7 1.0"/>
      </material>
    </visual>
    <collision>
      <geometry>
        <mesh filename="package://meshes/ur5/collision/upperarm.stl"/>
      </geometry>
    </collision>
    <inertial>
      <mass value="8.393"/>
      <origin rpy="0 0 0" xyz="0.0 0.0 0.28"/>
      <inertia ixx="0.22689067591036005" ixy="0.0" ixz="0.0" iyy="0.22689067591036005" iyz="0.0" izz="0.0151074"/>
    </inertial>
  </link>
  <joint name="elbow_joint" type="revolute">
    <parent link="upper_arm_link"/>
    <child link="forearm_link"/>
    <origin rpy="0.0 0.0 0.0" xyz="0.0 -0.1197 0.425"/>
    <axis xyz="0 1 0"/>
    <!-- <limit effort="150.0" lower="-3.14159265" upper="3.14159265" velocity="3.15"/> -->
    <limit effort="150.0" lower="-3.14159265" upper="3.14159265" velocity="0.5"/>
    <dynamics damping="0.0" friction="0.0"/>
  </joint>
  <link name="forearm_link">
    <visual>
      <geometry>
        <mesh filename="package://meshes/ur5/visual/forearm.dae"/>
      </geometry>
      <material name="LightGrey">
        <color rgba="0.7 0.7 0.7 1.0"/>
      </material>
    </visual>
    <collision>
      <geometry>
        <mesh filename="package://meshes/ur5/collision/forearm.stl"/>
      </geometry>
    </collision>
    <inertial>
      <mass value="2.275"/>
      <origin rpy="0 0 0" xyz="0.0 0.0 0.25"/>
      <inertia ixx="0.04944331355599999" ixy="0.0" ixz="0.0" iyy="0.04944331355599999" iyz="0.0" izz="0.004095"/>
    </inertial>
  </link>
  <joint name="wrist_1_joint" type="revolute">
    <parent link="forearm_link"/>
    <child link="wrist_1_link"/>
    <origin rpy="0.0 1.570796325 0.0" xyz="0.0 0.0 0.39225"/>
    <axis xyz="0 1 0"/>
    <!-- <limit effort="28.0" lower="-3.14159265" upper="3.14159265" velocity="3.2"/> -->
    <limit effort="28.0" lower="-3.14159265" upper="3.14159265" velocity="0.5"/>
    <dynamics damping="0.0" friction="0.0"/>
  </joint>
  <link name="wrist_1_link">
    <visual>
      <geometry>
        <mesh filename="package://meshes/ur5/visual/wrist1.dae"/>
      </geometry>
      <material name="LightGrey">
        <color rgba="0.7 0.7 0.7 1.0"/>
      </material>
    </visual>
    <collision>
      <geometry>
        <mesh filename="package://meshes/ur5/collision/wrist1.stl"/>
      </geometry>
    </collision>
    <inertial>
      <mass value="1.219"/>
      <origin rpy="0 0 0" xyz="0.0 0.0 0.0"/>
      <inertia ixx="0.11117275553087999" ixy="0.0" ixz="0.0" iyy="0.11117275553087999" iyz="0.0" izz="0.21942"/>
    </inertial>
  </link>
  <joint name="wrist_2_joint" type="revolute">
    <parent link="wrist_1_link"/>
    <child link="wrist_2_link"/>
    <origin rpy="0.0 0.0 0.0" xyz="0.0 0.093 0.0"/>
    <axis xyz="0 0 1"/>
    <!-- <limit effort="28.0" lower="-3.14159265" upper="3.14159265" velocity="3.2"/> -->
    <limit effort="28.0" lower="-3.14159265" upper="3.14159265" velocity="0.5"/>
    <dynamics damping="0.0" friction="0.0"/>
  </joint>
  <link name="wrist_2_link">
    <visual>
      <geometry>
        <mesh filename="package://meshes/ur5/visual/wrist2.dae"/>
      </geometry>
      <material name="LightGrey">
        <color rgba="0.7 0.7 0.7 1.0"/>
      </material>
    </visual>
    <collision>
      <geometry>
        <mesh filename="package://meshes/ur5/collision/wrist2.stl"/>
      </geometry>
    </collision>
    <inertial>
      <mass value="1.219"/>
      <origin rpy="0 0 0" xyz="0.0 0.0 0.0"/>
      <inertia ixx="0.11117275553087999" ixy="0.0" ixz="0.0" iyy="0.11117275553087999" iyz="0.0" izz="0.21942"/>
    </inertial>
  </link>
  <joint name="wrist_3_joint" type="revolute">
    <parent link="wrist_2_link"/>
    <child link="wrist_3_link"/>
    <origin rpy="0.0 0.0 0.0" xyz="0.0 0.0 0.09465"/>
    <axis xyz="0 1 0"/>
    <!-- <limit effort="28.0" lower="-3.14159265" upper="3.14159265" velocity="3.2"/> -->
    <limit effort="28.0" lower="-3.14159265" upper="3.14159265" velocity="0.5"/>
    <dynamics damping="0.0" friction="0.0"/>
  </joint>
  <link name="wrist_3_link">
    <visual>
      <geometry>
        <mesh filename="package://meshes/ur5/visual/wrist3.dae"/>
      </geometry>
      <material name="LightGrey">
        <color rgba="0.7 0.7 0.7 1.0"/>
      </material>
    </visual>
    <collision>
      <geometry>
        <mesh filename="package://meshes/ur5/collision/wrist3.stl"/>
      </geometry>
    </collision>
    <inertial>
      <mass value="0.1879"/>
      <origin rpy="0 0 0" xyz="0.0 0.0 0.0"/>
      <inertia ixx="0.017136473145408" ixy="0.0" ixz="0.0" iyy="0.017136473145408" iyz="0.0" izz="0.033822"/>
    </inertial>
  </link>
  <joint name="ee_fixed_joint" type="fixed">
    <parent link="wrist_3_link"/>
    <child link="ee_link"/>
    <origin rpy="0.0 0.0 1.570796325" xyz="0.0 0.0823 0.0"/>
  </joint>
  <link name="ee_link">
    <collision>
      <geometry>
        <box size="0.01 0.01 0.01"/>
      </geometry>
      <origin rpy="0 0 0" xyz="-0.01 0 0"/>
    </collision>
  </link>


  <transmission name="shoulder_pan_trans">
    <type>transmission_interface/SimpleTransmission</type>
    <joint name="shoulder_pan_joint">
      <hardwareInterface>hardware_interface/PositionJointInterface</hardwareInterface>
    </joint>
    <actuator name="shoulder_pan_motor">
      <mechanicalReduction>1</mechanicalReduction>
    </actuator>
  </transmission>
  <transmission name="shoulder_lift_trans">
    <type>transmission_interface/SimpleTransmission</type>
    <joint name="shoulder_lift_joint">
      <hardwareInterface>hardware_interface/PositionJointInterface</hardwareInterface>
    </joint>
    <actuator name="shoulder_lift_motor">
      <mechanicalReduction>1</mechanicalReduction>
    </actuator>
  </transmission>
  <transmission name="elbow_trans">
    <type>transmission_interface/SimpleTransmission</type>
    <joint name="elbow_joint">
      <hardwareInterface>hardware_interface/PositionJointInterface</hardwareInterface>
    </joint>
    <actuator name="elbow_motor">
      <mechanicalReduction>1</mechanicalReduction>
    </actuator>
  </transmission>
  <transmission name="wrist_1_trans">
    <type>transmission_interface/SimpleTransmission</type>
    <joint name="wrist_1_joint">
      <hardwareInterface>hardware_interface/PositionJointInterface</hardwareInterface>
    </joint>
    <actuator name="wrist_1_motor">
      <mechanicalReduction>1</mechanicalReduction>
    </actuator>
  </transmission>
  <transmission name="wrist_2_trans">
    <type>transmission_interface/SimpleTransmission</type>
    <joint name="wrist_2_joint">
      <hardwareInterface>hardware_interface/PositionJointInterface</hardwareInterface>
    </joint>
    <actuator name="wrist_2_motor">
      <mechanicalReduction>1</mechanicalReduction>
    </actuator>
  </transmission>
  <transmission name="wrist_3_trans">
    <type>transmission_interface/SimpleTransmission</type>
    <joint name="wrist_3_joint">
      <hardwareInterface>hardware_interface/PositionJointInterface</hardwareInterface>
    </joint>
    <actuator name="wrist_3_motor">
      <mechanicalReduction>1</mechanicalReduction>
    </actuator>
  </transmission>
  <!-- nothing to do here at the moment -->
  <!-- ROS base_link to UR 'Base' Coordinates transform -->

  <!-- Frame coincident with all-zeros TCP on UR controller -->
  <link name="tool0"/>
  <joint name="wrist_3_link-tool0_fixed_joint" type="fixed">
    <origin rpy="-1.570796325 0 0" xyz="0 0.0823 0"/>
    <parent link="wrist_3_link"/>
    <child link="tool0"/>
  </joint>
  <!-- mount the fts to the robot -->
  <joint name="fts_fix" type="fixed">
    <!--In most cases origin would be flange adapter plate: <origin xyz="0 0 0.009" rpy="0 0 0"/> /-->
    <origin rpy="0.0 0 -1.57" xyz="0.035 0 0.0"/>
    <parent link="ee_link"/>
    <child link="fts_robotside"/>
  </joint>
  <link name="fts_robotside">
    <inertial>
      <origin rpy="0 0 0" xyz="0 0 0.01875"/>
      <mass value="0.65"/>
      <inertia ixx="0.000661171875" ixy="0" ixz="0" iyy="0.000661171875" iyz="0" izz="0.00117"/>
    </inertial>
    <visual>
      <origin rpy="0 0 0" xyz="0 0 0"/>
      <geometry>
        <mesh filename="package://force_torque_sensor/meshes/visual/robotiq_fts300.stl"/>
      </geometry>
      <material name="black"/>
    </visual>
    <collision>
      <origin rpy="0 0 0" xyz="0 0 0"/>
      <geometry>
        <mesh filename="package://force_torque_sensor/meshes/collision/robotiq_fts300.stl"/>
      </geometry>
    </collision>
  </link>
  <!-- virtual measurement frame -->
  <joint name="measurment_joint" type="fixed">
    <origin rpy="0 0 0" xyz="0 0 0.01625"/>
    <parent link="fts_robotside"/>
    <child link="robotiq_force_torque_frame_id"/>
  </joint>
  <link name="robotiq_force_torque_frame_id"/>
  <!-- toolside frame -->
  <joint name="toolside_joint" type="fixed">
    <origin rpy="0 0 0" xyz="0 0 0.0375"/>
    <parent link="fts_robotside"/>
    <child link="fts_toolside"/>
  </joint>
  <link name="fts_toolside"/>
  <joint name="robotiq_85_base_joint" type="fixed">
    <parent link="fts_toolside"/>
    <child link="robotiq_85_base_link"/>
    <origin rpy="0.0 0.0 1.57" xyz="0.0 0.0 -0.037"/>
  </joint>
  <link name="robotiq_85_base_link">
    <visual>
      <geometry>
        <mesh filename="package://85_gripper/meshes/visual/robotiq_85_base_link.dae"/>
      </geometry>
    </visual>
    <collision>
      <geometry>
        <mesh filename="package://85_gripper/meshes/collision/robotiq_85_base_link.stl"/>
      </geometry>
    </collision>
    <inertial>
      <mass value="0.636951"/>
      <origin xyz="0.0 0.0 0.0"/>
      <inertia ixx="0.000380" ixy="0.000000" ixz="0.000000" iyx="0.000000" iyy="0.001110" iyz="0.000000" izx="0.000000" izy="0.000000" izz="0.001171"/>
    </inertial>
  </link>
  <joint name="robotiq_85_left_knuckle_joint" type="revolute">
    <parent link="robotiq_85_base_link"/>
    <child link="robotiq_85_left_knuckle_link"/>
    <axis xyz="0 0 1"/>
    <origin rpy="3.14159 0.0 0.0" xyz="0.05490451627 0.03060114443 0.0"/>
    <limit effort="50" lower="0.0" upper="0.804" velocity="0.5"/>
    <dynamics damping="100.0"/>
  </joint>
  <gazebo reference="robotiq_85_left_knuckle_link">
    <kp>1000000.0</kp>
    <kd>100.0</kd>
    <mu1>30.0</mu1>
    <mu2>30.0</mu2>
    <maxVel>1.0</maxVel>
    <minDepth>0.001</minDepth>
    <material>Gazebo/Grey</material>
  </gazebo>
  <joint name="robotiq_85_right_knuckle_joint" type="continuous">
    <parent link="robotiq_85_base_link"/>
    <child link="robotiq_85_right_knuckle_link"/>
    <axis xyz="0 0 1"/>
    <origin rpy="0.0 0.0 0.0" xyz="0.05490451627 -0.03060114443 0.0"/>
    <limit effort="50" lower="-3.14" upper="3.14" velocity="100.0"/>
    <mimic joint="robotiq_85_left_knuckle_joint"/>
    <dynamics damping="100.0"/>
  </joint>
  <gazebo reference="robotiq_85_right_knuckle_link">
    <kp>1000000.0</kp>
    <kd>100.0</kd>
    <mu1>30.0</mu1>
    <mu2>30.0</mu2>
    <maxVel>1.0</maxVel>
    <minDepth>0.001</minDepth>
    <material>Gazebo/Grey</material>
  </gazebo>
  <gazebo>
    <plugin filename="libroboticsgroup_gazebo_mimic_joint_plugin.so" name="{prefix}robotiq_85_right_knuckle_jointmimic_joint_plugin">
      <joint>robotiq_85_left_knuckle_joint</joint>
      <mimicJoint>robotiq_85_right_knuckle_joint</mimicJoint>
      <multiplier>1.0</multiplier>
      <offset>0</offset>
      <sensitiveness>0.0</sensitiveness>
      <!-- if absolute difference between setpoint and process value is below this threshold, do nothing; 0.0 = disable [rad] -->
      <maxEffort>10.0</maxEffort>
    </plugin>
  </gazebo>
  <link name="robotiq_85_left_knuckle_link">
    <visual>
      <geometry>
        <mesh filename="package://85_gripper/meshes/visual/robotiq_85_knuckle_link.dae"/>
      </geometry>
    </visual>
    <collision>
      <geometry>
        <mesh filename="package://85_gripper/meshes/collision/robotiq_85_knuckle_link.stl"/>
      </geometry>
    </collision>
    <inertial>
      <mass value="0.018491"/>
      <origin xyz="0.0 0.0 0.0"/>
      <inertia ixx="0.000009" ixy="-0.000001" ixz="0.000000" iyx="-0.000001" iyy="0.000001" iyz="0.000000" izx="0.000000" izy="0.000000" izz="0.000010"/>
    </inertial>
  </link>
  <link name="robotiq_85_right_knuckle_link">
    <visual>
      <geometry>
        <mesh filename="package://85_gripper/meshes/visual/robotiq_85_knuckle_link.dae"/>
      </geometry>
    </visual>
    <collision>
      <geometry>
        <mesh filename="package://85_gripper/meshes/collision/robotiq_85_knuckle_link.stl"/>
      </geometry>
    </collision>
    <inertial>
      <mass value="0.018491"/>
      <origin xyz="0.0 0.0 0.0"/>
      <inertia ixx="0.000009" ixy="-0.000001" ixz="0.000000" iyx="-0.000001" iyy="0.000001" iyz="0.000000" izx="0.000000" izy="0.000000" izz="0.000010"/>
    </inertial>
  </link>
  <joint name="robotiq_85_left_finger_joint" type="fixed">
    <parent link="robotiq_85_left_knuckle_link"/>
    <child link="robotiq_85_left_finger_link"/>
    <origin rpy="0 0 0" xyz="-0.00408552455 -0.03148604435 0.0"/>
  </joint>
  <joint name="robotiq_85_right_finger_joint" type="fixed">
    <parent link="robotiq_85_right_knuckle_link"/>
    <child link="robotiq_85_right_finger_link"/>
    <origin rpy="0 0 0" xyz="-0.00408552455 -0.03148604435 0.0"/>
  </joint>
  <link name="robotiq_85_left_finger_link">
    <visual>
      <geometry>
        <mesh filename="package://85_gripper/meshes/visual/robotiq_85_finger_link.dae"/>
      </geometry>
    </visual>
    <collision>
      <geometry>
        <mesh filename="package://85_gripper/meshes/collision/robotiq_85_finger_link.stl"/>
      </geometry>
    </collision>
    <inertial>
      <mass value="0.027309"/>
      <origin xyz="0.0 0.0 0.0"/>
      <inertia ixx="0.000003" ixy="-0.000002" ixz="0.000000" iyx="-0.000002" iyy="0.000021" iyz="0.000000" izx="0.000000" izy="0.000000" izz="0.000020"/>
    </inertial>
  </link>
  <link name="robotiq_85_right_finger_link">
    <visual>
      <geometry>
        <mesh filename="package://85_gripper/meshes/visual/robotiq_85_finger_link.dae"/>
      </geometry>
    </visual>
    <collision>
      <geometry>
        <mesh filename="package://85_gripper/meshes/collision/robotiq_85_finger_link.stl"/>
      </geometry>
    </collision>
    <inertial>
      <mass value="0.027309"/>
      <origin xyz="0.0 0.0 0.0"/>
      <inertia ixx="0.000003" ixy="-0.000002" ixz="0.000000" iyx="-0.000002" iyy="0.000021" iyz="0.000000" izx="0.000000" izy="0.000000" izz="0.000020"/>
    </inertial>
  </link>
  <joint name="robotiq_85_left_inner_knuckle_joint" type="continuous">
    <parent link="robotiq_85_base_link"/>
    <child link="robotiq_85_left_inner_knuckle_link"/>
    <axis xyz="0 0 1"/>
    <origin rpy="3.14159 0.0 0.0" xyz="0.06142 0.0127 0"/>
    <limit effort="0.1" lower="-3.14" upper="3.14" velocity="100.0"/>
    <mimic joint="robotiq_85_left_knuckle_joint" offset="0"/>
  </joint>
  <gazebo>
    <plugin filename="libroboticsgroup_gazebo_mimic_joint_plugin.so" name="robotiq_85_left_inner_knuckle_jointmimic_joint_plugin">
      <joint>robotiq_85_left_knuckle_joint</joint>
      <mimicJoint>robotiq_85_left_inner_knuckle_joint</mimicJoint>
      <multiplier>1.0</multiplier>
      <offset>0</offset>
      <sensitiveness>0.0</sensitiveness>
      <!-- if absolute difference between setpoint and process value is below this threshold, do nothing; 0.0 = disable [rad] -->
      <maxEffort>10.0</maxEffort>
    </plugin>
  </gazebo>
  <joint name="robotiq_85_right_inner_knuckle_joint" type="continuous">
    <parent link="robotiq_85_base_link"/>
    <child link="robotiq_85_right_inner_knuckle_link"/>
    <axis xyz="0 0 1"/>
    <origin rpy="0 0 0" xyz="0.06142 -0.0127 0"/>
    <limit effort="0.1" lower="-3.14" upper="3.14" velocity="100.0"/>
    <mimic joint="robotiq_85_left_knuckle_joint" offset="0"/>
  </joint>
  <gazebo>
    <plugin filename="libroboticsgroup_gazebo_mimic_joint_plugin.so" name="robotiq_85_right_inner_knuckle_jointmimic_joint_plugin">
      <joint>robotiq_85_left_knuckle_joint</joint>
      <mimicJoint>robotiq_85_right_inner_knuckle_joint</mimicJoint>
      <multiplier>1.0</multiplier>
      <offset>0</offset>
      <sensitiveness>0.0</sensitiveness>
      <!-- if absolute difference between setpoint and process value is below this threshold, do nothing; 0.0 = disable [rad] -->
      <maxEffort>10.0</maxEffort>
    </plugin>
  </gazebo>
  <link name="robotiq_85_left_inner_knuckle_link">
    <visual>
      <geometry>
        <mesh filename="package://85_gripper/meshes/visual/robotiq_85_inner_knuckle_link.dae"/>
      </geometry>
    </visual>
    <collision>
      <geometry>
        <mesh filename="package://85_gripper/meshes/collision/robotiq_85_inner_knuckle_link.stl"/>
      </geometry>
    </collision>
    <inertial>
      <mass value="0.029951"/>
      <origin xyz="0.0 0.0 0.0"/>
      <inertia ixx="0.000039" ixy="0.000000" ixz="0.000000" iyx="0.000000" iyy="0.000005" iyz="0.000000" izx="0.000000" izy="0.000000" izz="0.000035"/>
    </inertial>
  </link>
  <link name="robotiq_85_right_inner_knuckle_link">
    <visual>
      <geometry>
        <mesh filename="package://85_gripper/meshes/visual/robotiq_85_inner_knuckle_link.dae"/>
      </geometry>
    </visual>
    <collision>
      <geometry>
        <mesh filename="package://85_gripper/meshes/collision/robotiq_85_inner_knuckle_link.stl"/>
      </geometry>
    </collision>
    <inertial>
      <mass value="0.029951"/>
      <origin xyz="0.0 0.0 0.0"/>
      <inertia ixx="0.000039" ixy="0.000000" ixz="0.000000" iyx="0.000000" iyy="0.000005" iyz="0.000000" izx="0.000000" izy="0.000000" izz="0.000035"/>
    </inertial>
  </link>
  <joint name="robotiq_85_left_finger_tip_joint" type="continuous">
    <parent link="robotiq_85_left_inner_knuckle_link"/>
    <child link="robotiq_85_left_finger_tip_link"/>
    <axis xyz="0 0 1"/>
    <origin rpy="0.0 0.0 0.0" xyz="0.04303959807 -0.03759940821 0.0"/>
    <limit effort="0.1" lower="-3.14" upper="3.14" velocity="100.0"/>
    <mimic joint="robotiq_85_left_knuckle_joint" multiplier="-1"/>
  </joint>
  <gazebo>
    <plugin filename="libroboticsgroup_gazebo_mimic_joint_plugin.so" name="robotiq_85_left_finger_tip_jointmimic_joint_plugin">
      <joint>robotiq_85_left_knuckle_joint</joint>
      <mimicJoint>robotiq_85_left_finger_tip_joint</mimicJoint>
      <multiplier>1.0</multiplier>
      <offset>0</offset>
      <sensitiveness>0.0</sensitiveness>
      <!-- if absolute difference between setpoint and process value is below this threshold, do nothing; 0.0 = disable [rad] -->
      <maxEffort>10.0</maxEffort>
    </plugin>
  </gazebo>
  <joint name="robotiq_85_right_finger_tip_joint" type="continuous">
    <parent link="robotiq_85_right_inner_knuckle_link"/>
    <child link="robotiq_85_right_finger_tip_link"/>
    <axis xyz="0 0 1"/>
    <origin rpy="0.0 0.0 0.0" xyz="0.04303959807 -0.03759940821  0.0"/>
    <limit effort="0.1" lower="-3.14" upper="3.14" velocity="100.0"/>
    <mimic joint="robotiq_85_left_knuckle_joint" multiplier="-1"/>
  </joint>
  <gazebo>
    <plugin filename="libroboticsgroup_gazebo_mimic_joint_plugin.so" name="robotiq_85_right_finger_tip_jointmimic_joint_plugin">
      <joint>robotiq_85_left_knuckle_joint</joint>
      <mimicJoint>robotiq_85_right_finger_tip_joint</mimicJoint>
      <multiplier>1.0</multiplier>
      <offset>0</offset>
      <sensitiveness>0.0</sensitiveness>
      <!-- if absolute difference between setpoint and process value is below this threshold, do nothing; 0.0 = disable [rad] -->
      <maxEffort>10.0</maxEffort>
    </plugin>
  </gazebo>
  <link name="robotiq_85_left_finger_tip_link">
    <visual>
      <geometry>
        <mesh filename="package://85_gripper/meshes/visual/robotiq_85_finger_tip_link.dae"/>
      </geometry>
    </visual>
    <collision>
      <geometry>
        <mesh filename="package://85_gripper/meshes/collision/robotiq_85_finger_tip_link.stl"/>
      </geometry>
    </collision>
    <inertial>
      <mass value="0.019555"/>
      <origin xyz="0.0 0.0 0.0"/>
      <inertia ixx="0.000002" ixy="0.000000" ixz="0.000000" iyx="0.000000" iyy="0.000005" iyz="0.000000" izx="0.000000" izy="0.000000" izz="0.000006"/>
    </inertial>
  </link>
  <gazebo reference="robotiq_85_left_finger_tip_link">
    <kp>1000000.0</kp>
    <kd>100.0</kd>
    <mu1>30.0</mu1>
    <mu2>30.0</mu2>
    <maxVel>1.0</maxVel>
    <minDepth>0.001</minDepth>
    <material>Gazebo/Grey</material>
  </gazebo>
  <link name="robotiq_85_right_finger_tip_link">
    <visual>
      <geometry>
        <mesh filename="package://85_gripper/meshes/visual/robotiq_85_finger_tip_link.dae"/>
      </geometry>
    </visual>
    <collision>
      <geometry>
        <mesh filename="package://85_gripper/meshes/collision/robotiq_85_finger_tip_link.stl"/>
      </geometry>
    </collision>
    <inertial>
      <mass value="0.019555"/>
      <origin xyz="0.0 0.0 0.0"/>
      <inertia ixx="0.000002" ixy="0.000000" ixz="0.000000" iyx="0.000000" iyy="0.000005" iyz="0.000000" izx="0.000000" izy="0.000000" izz="0.000006"/>
    </inertial>
  </link>

  <!-- Camera Realsense D435i -->
  <!-- camera body, with origin at bottom screw mount -->
  <joint name="camera_joint" type="fixed">
    <origin rpy="0.0 0.0 0.0" xyz="0 0 -0.065"/>
    <parent link="ee_link"/>
    <child link="camera_bottom_screw_frame"/>
  </joint>
  <link name="camera_bottom_screw_frame"/>
  <joint name="camera_link_joint" type="fixed">
    <origin rpy="0 0 0" xyz="0.010600000000000002 0.0175 0.0125"/>
    <parent link="camera_bottom_screw_frame"/>
    <child link="camera_link"/>
  </joint>
  <link name="camera_link">
    <visual>
      <!-- the mesh origin is at front plate in between the two infrared camera axes -->
      <origin rpy="1.5707963267948966 0 1.5707963267948966" xyz="0.0043 -0.0175 0"/>
      <geometry>
        <mesh filename="package://meshes/d435.dae"/>
      </geometry>
      <material name="">
        <color rgba="0.01 0.01 0.01 1"/>
      </material>
    </visual>
    <collision>
      <origin rpy="1.5707963267948966 0 1.5707963267948966" xyz="0.0043 -0.0175 0"/>
      <!-- Stretch does not include this as it has a casing, here collision check is needed additionally -->
      <geometry>
        <mesh filename="package://meshes/d435.dae"/>
      </geometry>
      <geometry>
        <box size="0.02505 0.09 0.025"/>
      </geometry>
    </collision>
    <inertial>
      <!-- The following are not reliable values, and should not be used for modeling -->
      <mass value="0.072"/>
      <origin xyz="0 0 0"/>
      <inertia ixx="0.003881243" ixy="0.0" ixz="0.0" iyy="0.000498940" iyz="0.0" izz="0.003879257"/>
    </inertial>
  </link>
  <!-- camera depth joints and links -->
  <joint name="camera_depth_joint" type="fixed">
    <origin rpy="0 0 0" xyz="0 0 0"/>
    <parent link="camera_link"/>
    <child link="camera_depth_frame"/>
  </joint>
  <link name="camera_depth_frame"/>
  <joint name="camera_depth_optical_joint" type="fixed">
    <origin rpy="-1.5707963267948966 0 -1.5707963267948966" xyz="0 0 0"/>
    <parent link="camera_depth_frame"/>
    <child link="camera_depth_optical_frame"/>
  </joint>
  <link name="camera_depth_optical_frame"/>
  <!-- camera left IR joints and links -->
  <joint name="camera_infra1_joint" type="fixed">
    <origin rpy="0 0 0" xyz="0 0.0 0"/>
    <parent link="camera_link"/>
    <child link="camera_infra1_frame"/>
  </joint>
  <link name="camera_infra1_frame"/>
  <joint name="camera_infra1_optical_joint" type="fixed">
    <origin rpy="-1.5707963267948966 0 -1.5707963267948966" xyz="0 0 0"/>
    <parent link="camera_infra1_frame"/>
    <child link="camera_infra1_optical_frame"/>
  </joint>
  <link name="camera_infra1_optical_frame"/>
  <!-- camera right IR joints and links -->
  <joint name="camera_infra2_joint" type="fixed">
    <origin rpy="0 0 0" xyz="0 -0.05 0"/>
    <parent link="camera_link"/>
    <child link="camera_infra2_frame"/>
  </joint>
  <link name="camera_infra2_frame"/>
  <joint name="camera_infra2_optical_joint" type="fixed">
    <origin rpy="-1.5707963267948966 0 -1.5707963267948966" xyz="0 0 0"/>
    <parent link="camera_infra2_frame"/>
    <child link="camera_infra2_optical_frame"/>
  </joint>
  <link name="camera_infra2_optical_frame"/>
  <!-- camera color joints and links -->
  <joint name="camera_color_joint" type="fixed">
    <origin rpy="0 0 0" xyz="0 0.015 0"/>
    <parent link="camera_link"/>
    <child link="camera_color_frame"/>
  </joint>
  <link name="camera_color_frame"/>
  <joint name="camera_color_optical_joint" type="fixed">
    <origin rpy="-1.5707963267948966 0 -1.5707963267948966" xyz="0 0 0"/>
    <parent link="camera_color_frame"/>
    <child link="camera_color_optical_frame"/>
  </joint>
  <link name="camera_color_optical_frame"/>
  <joint name="camera_color_optical_rotated_joint" type="fixed">
    <origin rpy="0 0 -1.5707963267948966" xyz="0 0 0"/>
    <parent link="camera_color_optical_frame"/>
    <child link="camera_color_optical_frame_rotated"/>
  </joint>
  <link name="camera_color_optical_frame_rotated"/>
  <link name="camera_accel_frame"/>
  <link name="camera_accel_optical_frame"/>
  <link name="camera_gyro_frame"/>
  <link name="camera_gyro_optical_frame"/>
  <joint name="camera_accel_joint" type="fixed">
    <origin rpy="0 0 0" xyz="-0.01174 -0.00552 0.0051"/>
    <parent link="camera_link"/>
    <child link="camera_accel_frame"/>
  </joint>
  <joint name="camera_accel_optical_joint" type="fixed">
    <origin rpy="-1.5707963267948966 0 -1.5707963267948966" xyz="0 0 0"/>
    <parent link="camera_accel_frame"/>
    <child link="camera_accel_optical_frame"/>
  </joint>
  <joint name="camera_gyro_joint" type="fixed">
    <origin rpy="0 0 0" xyz="-0.01174 -0.00552 0.0051"/>
    <parent link="camera_link"/>
    <child link="camera_gyro_frame"/>
  </joint>
  <joint name="camera_gyro_optical_joint" type="fixed">
    <origin rpy="-1.5707963267948966 0 -1.5707963267948966" xyz="0 0 0"/>
    <parent link="camera_gyro_frame"/>
    <child link="camera_gyro_optical_frame"/>
  </joint>

  <gazebo reference="robotiq_85_right_finger_tip_link">
    <kp>1000000.0</kp>
    <kd>100.0</kd>
    <mu1>30.0</mu1>
    <mu2>30.0</mu2>
    <maxVel>1.0</maxVel>
    <minDepth>0.001</minDepth>
    <material>Gazebo/Grey</material>
  </gazebo>
  <transmission name="robotiq_85_left_knuckle_trans">
    <type>transmission_interface/SimpleTransmission</type>
    <joint name="robotiq_85_left_knuckle_joint">
      <hardwareInterface>hardware_interface/PositionJointInterface</hardwareInterface>
    </joint>
    <actuator name="robotiq_85_left_knuckle_motor">
      <mechanicalReduction>1</mechanicalReduction>
      <hardwareInterface>hardware_interface/PositionJointInterface</hardwareInterface>
    </actuator>
  </transmission>
  <gazebo>
    <!-- loading plugin: mimic joints works in gazebo now -->
    <plugin filename="libroboticsgroup_gazebo_mimic_joint_plugin.so" name="mimic_robotiq_85_1">
      <joint>robotiq_85_left_knuckle_joint</joint>
      <mimicJoint>robotiq_85_right_knuckle_joint</mimicJoint>
      <!--multiplier>1.0</multiplier>
                <offset>0.0</offset-->
    </plugin>
    <plugin filename="libroboticsgroup_gazebo_mimic_joint_plugin.so" name="mimic_robotiq_85_2">
      <joint>robotiq_85_left_knuckle_joint</joint>
      <mimicJoint>robotiq_85_left_inner_knuckle_joint</mimicJoint>
      <!--multiplier>1.0</multiplier>
                <offset>0.0</offset-->
    </plugin>
    <plugin filename="libroboticsgroup_gazebo_mimic_joint_plugin.so" name="mimic_robotiq_85_3">
      <joint>robotiq_85_left_knuckle_joint</joint>
      <mimicJoint>robotiq_85_right_inner_knuckle_joint</mimicJoint>
      <!--multiplier>1.0</multiplier>
                <offset>0.0</offset-->
    </plugin>
    <plugin filename="libroboticsgroup_gazebo_mimic_joint_plugin.so" name="mimic_robotiq_85_4">
      <joint>robotiq_85_left_knuckle_joint</joint>
      <mimicJoint>robotiq_85_left_finger_tip_joint</mimicJoint>
      <multiplier>-1.0</multiplier>
      <offset>0.0</offset>
    </plugin>
    <plugin filename="libroboticsgroup_gazebo_mimic_joint_plugin.so" name="mimic_robotiq_85_5">
      <joint>robotiq_85_left_knuckle_joint</joint>
      <mimicJoint>robotiq_85_right_finger_tip_joint</mimicJoint>
      <multiplier>-1.0</multiplier>
      <offset>0.0</offset>
    </plugin>
  </gazebo>
</robot>

